<sdf version='1.7'>
  <world name='default'>
    <light name='sun' type='directional'>
      <cast_shadows>1</cast_shadows>
      <pose>0 0 10 0 -0 0</pose>
      <diffuse>0.8 0.8 0.8 1</diffuse>
      <specular>0.2 0.2 0.2 1</specular>
      <attenuation>
        <range>1000</range>
        <constant>0.9</constant>
        <linear>0.01</linear>
        <quadratic>0.001</quadratic>
      </attenuation>
      <direction>-0.5 0.1 -0.9</direction>
      <spot>
        <inner_angle>0</inner_angle>
        <outer_angle>0</outer_angle>
        <falloff>0</falloff>
      </spot>
    </light>
    <model name='ground_plane'>
      <static>1</static>
      <link name='link'>
        <collision name='collision'>
          <geometry>
            <plane>
              <normal>0 0 1</normal>
              <size>100 100</size>
            </plane>
          </geometry>
          <surface>
            <friction>
              <ode>
                <mu>100</mu>
                <mu2>50</mu2>
              </ode>
              <torsional>
                <ode/>
              </torsional>
            </friction>
            <contact>
              <ode/>
            </contact>
            <bounce/>
          </surface>
          <max_contacts>10</max_contacts>
        </collision>
        <visual name='visual'>
          <cast_shadows>0</cast_shadows>
          <geometry>
            <plane>
              <normal>0 0 1</normal>
              <size>100 100</size>
            </plane>
          </geometry>
          <material>
            <script>
              <uri>file://media/materials/scripts/gazebo.material</uri>
              <name>Gazebo/Grey</name>
            </script>
          </material>
        </visual>
        <self_collide>0</self_collide>
        <enable_wind>0</enable_wind>
        <kinematic>0</kinematic>
      </link>
    </model>
    <gravity>0 0 -9.8</gravity>
    <magnetic_field>6e-06 2.3e-05 -4.2e-05</magnetic_field>
    <atmosphere type='adiabatic'/>
    <physics type='ode'>
      <max_step_size>0.001</max_step_size>
      <real_time_factor>1</real_time_factor>
      <real_time_update_rate>1000</real_time_update_rate>
    </physics>
    <scene>
      <ambient>0.4 0.4 0.4 1</ambient>
      <background>0.7 0.7 0.7 1</background>
      <shadows>1</shadows>
    </scene>
    <audio>
      <device>default</device>
    </audio>
    <wind/>
    <spherical_coordinates>
      <surface_model>EARTH_WGS84</surface_model>
      <latitude_deg>0</latitude_deg>
      <longitude_deg>0</longitude_deg>
      <elevation>0</elevation>
      <heading_deg>0</heading_deg>
    </spherical_coordinates>
    <model name='service_robot'>
      <link name='base_link'>
        <inertial>
          <pose>0.001828 -3e-06 0.058688 0 -0 0</pose>
          <mass>8.513</mass>
          <inertia>
            <ixx>0.170735</ixx>
            <ixy>3.70613e-06</ixy>
            <ixz>-0.00559479</ixz>
            <iyy>0.173062</iyy>
            <iyz>8.91057e-06</iyz>
            <izz>0.117827</izz>
          </inertia>
        </inertial>
        <collision name='base_link_collision'>
          <pose>0 0 0 0 -0 0</pose>
          <geometry>
            <box>
              <size>0.35 0.35 0.1</size>
            </box>
          </geometry>
          <surface>
            <contact>
              <ode>
                <kp>1e+06</kp>
                <kd>100</kd>
              </ode>
            </contact>
            <friction>
              <ode>
                <mu>0.5</mu>
                <mu2>0.5</mu2>
              </ode>
              <torsional>
                <ode/>
              </torsional>
            </friction>
            <bounce/>
          </surface>
          <max_contacts>10</max_contacts>
        </collision>
        <collision name='base_link_fixed_joint_lump__body_collision_1'>
          <pose>0.15 -0.000239 0.225 0 -0 3.14</pose>
          <geometry>
            <box>
              <size>0.05 0.35 0.35</size>
            </box>
          </geometry>
          <surface>
            <contact>
              <ode>
                <kp>1e+06</kp>
                <kd>100</kd>
              </ode>
            </contact>
            <friction>
              <ode>
                <mu>0.2</mu>
                <mu2>0.2</mu2>
              </ode>
              <torsional>
                <ode/>
              </torsional>
            </friction>
            <bounce/>
          </surface>
          <max_contacts>10</max_contacts>
        </collision>
        <collision name='base_link_fixed_joint_lump__camera_link_collision_2'>
          <pose>0.1875 -0.000299 0.37 0 -0 3.14</pose>
          <geometry>
            <box>
              <size>0.025 0.024 0.009</size>
            </box>
          </geometry>
          <surface>
            <contact>
              <ode/>
            </contact>
            <friction>
              <ode/>
              <torsional>
                <ode/>
              </torsional>
            </friction>
            <bounce/>
          </surface>
          <max_contacts>10</max_contacts>
        </collision>
        <collision name='base_link_fixed_joint_lump__front_plate_bottom_collision_3'>
          <pose>0 0 0.13 0 -0 3.14</pose>
          <geometry>
            <box>
              <size>0.25 0.35 0.03</size>
            </box>
          </geometry>
          <surface>
            <contact>
              <ode/>
            </contact>
            <friction>
              <ode/>
              <torsional>
                <ode/>
              </torsional>
            </friction>
            <bounce/>
          </surface>
          <max_contacts>10</max_contacts>
        </collision>
        <collision name='base_link_fixed_joint_lump__front_plate_middle_collision_4'>
          <pose>0 0 0.23 0 -0 3.14</pose>
          <geometry>
            <box>
              <size>0.25 0.35 0.03</size>
            </box>
          </geometry>
          <surface>
            <contact>
              <ode/>
            </contact>
            <friction>
              <ode/>
              <torsional>
                <ode/>
              </torsional>
            </friction>
            <bounce/>
          </surface>
          <max_contacts>10</max_contacts>
        </collision>
        <collision name='base_link_fixed_joint_lump__front_plate_top_collision_5'>
          <pose>0 0 0.33 0 -0 3.14</pose>
          <geometry>
            <box>
              <size>0.25 0.35 0.03</size>
            </box>
          </geometry>
          <surface>
            <contact>
              <ode/>
            </contact>
            <friction>
              <ode/>
              <torsional>
                <ode/>
              </torsional>
            </friction>
            <bounce/>
          </surface>
          <max_contacts>10</max_contacts>
        </collision>
        <collision name='base_link_fixed_joint_lump__lidar_link_collision_6'>
          <pose>0.15 -0.000239 0.42 0 -0 3.14</pose>
          <geometry>
            <cylinder>
              <length>0.04</length>
              <radius>0.035</radius>
            </cylinder>
          </geometry>
          <surface>
            <contact>
              <ode/>
            </contact>
            <friction>
              <ode/>
              <torsional>
                <ode/>
              </torsional>
            </friction>
            <bounce/>
          </surface>
          <max_contacts>10</max_contacts>
        </collision>
        <visual name='base_link_visual'>
          <pose>0 0 0 0 -0 0</pose>
          <geometry>
            <box>
              <size>0.35 0.35 0.1</size>
            </box>
          </geometry>
          <material>
            <script>
              <name>Gazebo/Orange</name>
              <uri>file://media/materials/scripts/gazebo.material</uri>
            </script>
          </material>
        </visual>
        <visual name='base_link_fixed_joint_lump__body_visual_1'>
          <pose>0.15 -0.000239 0.225 0 -0 3.14</pose>
          <geometry>
            <box>
              <size>0.05 0.35 0.35</size>
            </box>
          </geometry>
          <material>
            <script>
              <name>Gazebo/Black</name>
              <uri>file://media/materials/scripts/gazebo.material</uri>
            </script>
          </material>
        </visual>
        <visual name='base_link_fixed_joint_lump__camera_link_visual_2'>
          <pose>0.1875 -0.000299 0.37 0 -0 3.14</pose>
          <geometry>
            <box>
              <size>0.025 0.024 0.009</size>
            </box>
          </geometry>
          <material>
            <script>
              <name>Gazebo/Yellow</name>
              <uri>file://media/materials/scripts/gazebo.material</uri>
            </script>
          </material>
        </visual>
        <visual name='base_link_fixed_joint_lump__front_plate_bottom_visual_3'>
          <pose>0 0 0.13 0 -0 3.14</pose>
          <geometry>
            <box>
              <size>0.25 0.35 0.03</size>
            </box>
          </geometry>
          <material>
            <script>
              <name>Gazebo/Blue</name>
              <uri>file://media/materials/scripts/gazebo.material</uri>
            </script>
          </material>
        </visual>
        <visual name='base_link_fixed_joint_lump__front_plate_middle_visual_4'>
          <pose>0 0 0.23 0 -0 3.14</pose>
          <geometry>
            <box>
              <size>0.25 0.35 0.03</size>
            </box>
          </geometry>
          <material>
            <script>
              <name>Gazebo/Blue</name>
              <uri>file://media/materials/scripts/gazebo.material</uri>
            </script>
          </material>
        </visual>
        <visual name='base_link_fixed_joint_lump__front_plate_top_visual_5'>
          <pose>0 0 0.33 0 -0 3.14</pose>
          <geometry>
            <box>
              <size>0.25 0.35 0.03</size>
            </box>
          </geometry>
          <material>
            <script>
              <name>Gazebo/Blue</name>
              <uri>file://media/materials/scripts/gazebo.material</uri>
            </script>
          </material>
        </visual>
        <visual name='base_link_fixed_joint_lump__lidar_link_visual_6'>
          <pose>0.15 -0.000239 0.42 0 -0 3.14</pose>
          <geometry>
            <cylinder>
              <length>0.04</length>
              <radius>0.035</radius>
            </cylinder>
          </geometry>
          <material>
            <script>
              <name>Gazebo/Green</name>
              <uri>file://media/materials/scripts/gazebo.material</uri>
            </script>
          </material>
        </visual>
        <visual name='base_link_fixed_joint_lump__imu_link_visual_7'>
          <pose>0 0 0.05 0 -0 0</pose>
          <geometry>
            <box>
              <size>0.02 0.02 0.02</size>
            </box>
          </geometry>
        </visual>
        <self_collide>0</self_collide>
        <sensor name='pi_camera' type='camera'>
          <update_rate>30</update_rate>
          <camera name='head'>
            <horizontal_fov>1.0856</horizontal_fov>
            <image>
              <width>1920</width>
              <height>1080</height>
              <format>R8G8B8</format>
            </image>
            <clip>
              <near>0.03</near>
              <far>100</far>
            </clip>
            <noise>
              <type>gaussian</type>
              <mean>0</mean>
              <stddev>0.007</stddev>
            </noise>
          </camera>
          <plugin name='camera_controller' filename='libgazebo_ros_camera.so'>
            <alwaysOn>1</alwaysOn>
            <updateRate>30.0</updateRate>
            <cameraName>pi_camera</cameraName>
            <imageTopicName>image_raw</imageTopicName>
            <cameraInfoTopicName>camera_info</cameraInfoTopicName>
            <frameName>camera_link</frameName>
          </plugin>
          <pose>0.1875 -0.000299 0.37 0 -0 3.14</pose>
        </sensor>
        <sensor name='lidar' type='ray'>
          <always_on>1</always_on>
          <visualize>1</visualize>
          <update_rate>5</update_rate>
          <ray>
            <scan>
              <horizontal>
                <samples>360</samples>
                <resolution>1</resolution>
                <min_angle>0</min_angle>
                <max_angle>6.28319</max_angle>
              </horizontal>
              <vertical>
                <samples>1</samples>
                <min_angle>0</min_angle>
                <max_angle>0</max_angle>
              </vertical>
            </scan>
            <range>
              <min>0.12</min>
              <max>12</max>
              <resolution>0.015</resolution>
            </range>
            <noise>
              <type>gaussian</type>
              <mean>0</mean>
              <stddev>0.01</stddev>
            </noise>
          </ray>
          <plugin name='scan' filename='libgazebo_ros_ray_sensor.so'>
            <ros>
              <remapping>~/out:=scan</remapping>
            </ros>
            <output_type>sensor_msgs/LaserScan</output_type>
            <frame_name>lidar_link</frame_name>
          </plugin>
          <pose>0.15 -0.000239 0.42 0 -0 3.14</pose>
        </sensor>
        <gravity>1</gravity>
        <sensor name='imu_sensor' type='imu'>
          <always_on>1</always_on>
          <update_rate>100</update_rate>
          <visualize>1</visualize>
          <imu>
            <angular_velocity>
              <x>
                <noise type='gaussian'>
                  <mean>0</mean>
                  <stddev>0.00033</stddev>
                  <bias_mean>0</bias_mean>
                  <bias_stddev>0.0002</bias_stddev>
                </noise>
              </x>
              <y>
                <noise type='gaussian'>
                  <mean>0</mean>
                  <stddev>0.00033</stddev>
                  <bias_mean>0</bias_mean>
                  <bias_stddev>0.0002</bias_stddev>
                </noise>
              </y>
              <z>
                <noise type='gaussian'>
                  <mean>0</mean>
                  <stddev>0.00033</stddev>
                  <bias_mean>0</bias_mean>
                  <bias_stddev>0.0002</bias_stddev>
                </noise>
              </z>
            </angular_velocity>
            <linear_acceleration>
              <x>
                <noise type='gaussian'>
                  <mean>0</mean>
                  <stddev>0.04</stddev>
                  <bias_mean>0</bias_mean>
                  <bias_stddev>0.005</bias_stddev>
                </noise>
              </x>
              <y>
                <noise type='gaussian'>
                  <mean>0</mean>
                  <stddev>0.04</stddev>
                  <bias_mean>0</bias_mean>
                  <bias_stddev>0.005</bias_stddev>
                </noise>
              </y>
              <z>
                <noise type='gaussian'>
                  <mean>0</mean>
                  <stddev>0.04</stddev>
                  <bias_mean>0</bias_mean>
                  <bias_stddev>0.006</bias_stddev>
                </noise>
              </z>
            </linear_acceleration>
          </imu>
          <plugin name='imu_plugin' filename='libgazebo_ros_imu_sensor.so'>
            <ros>
              <namespace>/</namespace>
              <remapping>~/out:=imu/data</remapping>
            </ros>
            <initial_orientation_as_reference>0</initial_orientation_as_reference>
            <frame_name>imu_link</frame_name>
            <gaussian_noise>0.00033</gaussian_noise>
            <updateRate>100.0</updateRate>
            <bodyName>imu_link</bodyName>
            <topicName>imu/data</topicName>
            <serviceName>imu_service</serviceName>
            <xyzOffset>0 0 0</xyzOffset>
            <rpyOffset>0 0 0</rpyOffset>
          </plugin>
          <pose>0 0 0.05 0 -0 0</pose>
        </sensor>
        <enable_wind>0</enable_wind>
        <kinematic>0</kinematic>
      </link>
      <joint name='wheel_back_left_joint' type='revolute'>
        <pose relative_to='base_link'>-0.175 0.2 0 -1.5708 0 0</pose>
        <parent>base_link</parent>
        <child>wheel_back_left</child>
        <axis>
          <xyz>0 0 1</xyz>
          <limit>
            <effort>0.32</effort>
            <velocity>0.44</velocity>
            <lower>-1e+16</lower>
            <upper>1e+16</upper>
          </limit>
          <dynamics>
            <damping>0.1</damping>
            <friction>0.1</friction>
            <spring_reference>0</spring_reference>
            <spring_stiffness>0</spring_stiffness>
          </dynamics>
        </axis>
        <physics>
          <provide_feedback>1</provide_feedback>
          <ode>
            <implicit_spring_damper>1</implicit_spring_damper>
            <cfm_damping>1</cfm_damping>
            <limit>
              <cfm>0</cfm>
              <erp>0.2</erp>
            </limit>
            <provide_feedback>1</provide_feedback>
          </ode>
        </physics>
      </joint>
      <link name='wheel_back_left'>
        <pose relative_to='wheel_back_left_joint'>0 0 0 0 -0 0</pose>
        <inertial>
          <pose>0 0 0 0 -0 0</pose>
          <mass>0.375</mass>
          <inertia>
            <ixx>0.001</ixx>
            <ixy>0</ixy>
            <ixz>0</ixz>
            <iyy>0.001</iyy>
            <iyz>0</iyz>
            <izz>0.001</izz>
          </inertia>
        </inertial>
        <collision name='wheel_back_left_collision'>
          <pose>0 0 0 0 -0 0</pose>
          <geometry>
            <cylinder>
              <length>0.05</length>
              <radius>0.07</radius>
            </cylinder>
          </geometry>
          <surface>
            <contact>
              <ode>
                <kp>1e+06</kp>
                <kd>100</kd>
              </ode>
            </contact>
            <friction>
              <ode>
                <mu>0.7</mu>
                <mu2>0.3</mu2>
                <fdir1>1 0 0</fdir1>
              </ode>
              <torsional>
                <ode/>
              </torsional>
            </friction>
            <bounce/>
          </surface>
          <max_contacts>10</max_contacts>
        </collision>
        <visual name='wheel_back_left_visual'>
          <pose>0 0 0 0 -0 0</pose>
          <geometry>
            <cylinder>
              <length>0.05</length>
              <radius>0.07</radius>
            </cylinder>
          </geometry>
          <material>
            <script>
              <name>Gazebo/Yellow</name>
              <uri>file://media/materials/scripts/gazebo.material</uri>
            </script>
          </material>
        </visual>
        <gravity>1</gravity>
        <self_collide>0</self_collide>
        <enable_wind>0</enable_wind>
        <kinematic>0</kinematic>
      </link>
      <joint name='wheel_back_right_joint' type='revolute'>
        <pose relative_to='base_link'>-0.175 -0.2 0 -1.5708 0 0</pose>
        <parent>base_link</parent>
        <child>wheel_back_right</child>
        <axis>
          <xyz>0 0 1</xyz>
          <limit>
            <effort>0.32</effort>
            <velocity>0.44</velocity>
            <lower>-1e+16</lower>
            <upper>1e+16</upper>
          </limit>
          <dynamics>
            <damping>0.1</damping>
            <friction>0.1</friction>
            <spring_reference>0</spring_reference>
            <spring_stiffness>0</spring_stiffness>
          </dynamics>
        </axis>
        <physics>
          <provide_feedback>1</provide_feedback>
          <ode>
            <implicit_spring_damper>1</implicit_spring_damper>
            <cfm_damping>1</cfm_damping>
            <limit>
              <cfm>0</cfm>
              <erp>0.2</erp>
            </limit>
            <provide_feedback>1</provide_feedback>
          </ode>
        </physics>
      </joint>
      <link name='wheel_back_right'>
        <pose relative_to='wheel_back_right_joint'>0 0 0 0 -0 0</pose>
        <inertial>
          <pose>0 0 0 0 -0 0</pose>
          <mass>0.375</mass>
          <inertia>
            <ixx>0.001</ixx>
            <ixy>0</ixy>
            <ixz>0</ixz>
            <iyy>0.001</iyy>
            <iyz>0</iyz>
            <izz>0.001</izz>
          </inertia>
        </inertial>
        <collision name='wheel_back_right_collision'>
          <pose>0 0 0 0 -0 0</pose>
          <geometry>
            <cylinder>
              <length>0.05</length>
              <radius>0.07</radius>
            </cylinder>
          </geometry>
          <surface>
            <contact>
              <ode>
                <kp>1e+06</kp>
                <kd>100</kd>
              </ode>
            </contact>
            <friction>
              <ode>
                <mu>0.7</mu>
                <mu2>0.3</mu2>
                <fdir1>1 0 0</fdir1>
              </ode>
              <torsional>
                <ode/>
              </torsional>
            </friction>
            <bounce/>
          </surface>
          <max_contacts>10</max_contacts>
        </collision>
        <visual name='wheel_back_right_visual'>
          <pose>0 0 0 0 -0 0</pose>
          <geometry>
            <cylinder>
              <length>0.05</length>
              <radius>0.07</radius>
            </cylinder>
          </geometry>
          <material>
            <script>
              <name>Gazebo/Yellow</name>
              <uri>file://media/materials/scripts/gazebo.material</uri>
            </script>
          </material>
        </visual>
        <gravity>1</gravity>
        <self_collide>0</self_collide>
        <enable_wind>0</enable_wind>
        <kinematic>0</kinematic>
      </link>
      <joint name='wheel_front_left_joint' type='revolute'>
        <pose relative_to='base_link'>0.175 0.2 0 -1.5708 0 0</pose>
        <parent>base_link</parent>
        <child>wheel_front_left</child>
        <axis>
          <xyz>0 0 1</xyz>
          <limit>
            <effort>0.32</effort>
            <velocity>0.44</velocity>
            <lower>-1e+16</lower>
            <upper>1e+16</upper>
          </limit>
          <dynamics>
            <damping>0.1</damping>
            <friction>0.1</friction>
            <spring_reference>0</spring_reference>
            <spring_stiffness>0</spring_stiffness>
          </dynamics>
        </axis>
        <physics>
          <provide_feedback>1</provide_feedback>
          <ode>
            <implicit_spring_damper>1</implicit_spring_damper>
            <cfm_damping>1</cfm_damping>
            <limit>
              <cfm>0</cfm>
              <erp>0.2</erp>
            </limit>
            <provide_feedback>1</provide_feedback>
          </ode>
        </physics>
      </joint>
      <link name='wheel_front_left'>
        <pose relative_to='wheel_front_left_joint'>0 0 0 0 -0 0</pose>
        <inertial>
          <pose>0 0 0 0 -0 0</pose>
          <mass>0.375</mass>
          <inertia>
            <ixx>0.0005</ixx>
            <ixy>0</ixy>
            <ixz>0</ixz>
            <iyy>0.0005</iyy>
            <iyz>0</iyz>
            <izz>0.0009</izz>
          </inertia>
        </inertial>
        <collision name='wheel_front_left_collision'>
          <pose>0 0 0 0 -0 0</pose>
          <geometry>
            <cylinder>
              <length>0.05</length>
              <radius>0.07</radius>
            </cylinder>
          </geometry>
          <surface>
            <contact>
              <ode>
                <kp>1e+06</kp>
                <kd>100</kd>
              </ode>
            </contact>
            <friction>
              <ode>
                <mu>0.7</mu>
                <mu2>0.3</mu2>
                <fdir1>1 0 0</fdir1>
              </ode>
              <torsional>
                <ode/>
              </torsional>
            </friction>
            <bounce/>
          </surface>
          <max_contacts>10</max_contacts>
        </collision>
        <visual name='wheel_front_left_visual'>
          <pose>0 0 0 0 -0 0</pose>
          <geometry>
            <cylinder>
              <length>0.05</length>
              <radius>0.07</radius>
            </cylinder>
          </geometry>
          <material>
            <script>
              <name>Gazebo/Yellow</name>
              <uri>file://media/materials/scripts/gazebo.material</uri>
            </script>
          </material>
        </visual>
        <gravity>1</gravity>
        <self_collide>0</self_collide>
        <enable_wind>0</enable_wind>
        <kinematic>0</kinematic>
      </link>
      <joint name='wheel_front_right_joint' type='revolute'>
        <pose relative_to='base_link'>0.175 -0.2 0 -1.5708 0 0</pose>
        <parent>base_link</parent>
        <child>wheel_front_right</child>
        <axis>
          <xyz>0 0 1</xyz>
          <limit>
            <effort>0.32</effort>
            <velocity>0.44</velocity>
            <lower>-1e+16</lower>
            <upper>1e+16</upper>
          </limit>
          <dynamics>
            <damping>0.1</damping>
            <friction>0.1</friction>
            <spring_reference>0</spring_reference>
            <spring_stiffness>0</spring_stiffness>
          </dynamics>
        </axis>
        <physics>
          <provide_feedback>1</provide_feedback>
          <ode>
            <implicit_spring_damper>1</implicit_spring_damper>
            <cfm_damping>1</cfm_damping>
            <limit>
              <cfm>0</cfm>
              <erp>0.2</erp>
            </limit>
            <provide_feedback>1</provide_feedback>
          </ode>
        </physics>
      </joint>
      <link name='wheel_front_right'>
        <pose relative_to='wheel_front_right_joint'>0 0 0 0 -0 0</pose>
        <inertial>
          <pose>0 0 0 0 -0 0</pose>
          <mass>0.375</mass>
          <inertia>
            <ixx>0.001</ixx>
            <ixy>0</ixy>
            <ixz>0</ixz>
            <iyy>0.001</iyy>
            <iyz>0</iyz>
            <izz>0.001</izz>
          </inertia>
        </inertial>
        <collision name='wheel_front_right_collision'>
          <pose>0 0 0 0 -0 0</pose>
          <geometry>
            <cylinder>
              <length>0.05</length>
              <radius>0.07</radius>
            </cylinder>
          </geometry>
          <surface>
            <contact>
              <ode>
                <kp>1e+06</kp>
                <kd>100</kd>
              </ode>
            </contact>
            <friction>
              <ode>
                <mu>0.7</mu>
                <mu2>0.3</mu2>
                <fdir1>1 0 0</fdir1>
              </ode>
              <torsional>
                <ode/>
              </torsional>
            </friction>
            <bounce/>
          </surface>
          <max_contacts>10</max_contacts>
        </collision>
        <visual name='wheel_front_right_visual'>
          <pose>0 0 0 0 -0 0</pose>
          <geometry>
            <cylinder>
              <length>0.05</length>
              <radius>0.07</radius>
            </cylinder>
          </geometry>
          <material>
            <script>
              <name>Gazebo/Yellow</name>
              <uri>file://media/materials/scripts/gazebo.material</uri>
            </script>
          </material>
        </visual>
        <gravity>1</gravity>
        <self_collide>0</self_collide>
        <enable_wind>0</enable_wind>
        <kinematic>0</kinematic>
      </link>
      <static>0</static>
      <plugin name='gazebo_ros2_control' filename='libgazebo_ros2_control.so'>
        <robot_param>robot_description</robot_param>
        <robot_param_node>robot_state_publisher</robot_param_node>
        <parameters>/home/ammar/Robotics/Graduation_Project/ACSAR_ws/install/robot_control/share/robot_control/config/diff_controller.yaml</parameters>
      </plugin>
      <pose>0 0 0 0 -0 0</pose>
    </model>
    <state world_name='default'>
      <sim_time>257 241000000</sim_time>
      <real_time>100 990068025</real_time>
      <wall_time>1735837751 313875919</wall_time>
      <iterations>100163</iterations>
      <model name='ground_plane'>
        <pose>0 0 0 0 -0 0</pose>
        <scale>1 1 1</scale>
        <link name='link'>
          <pose>0 0 0 0 -0 0</pose>
          <velocity>0 0 0 0 -0 0</velocity>
          <acceleration>0 0 0 0 -0 0</acceleration>
          <wrench>0 0 0 0 -0 0</wrench>
        </link>
      </model>
      <model name='service_robot'>
        <pose>0.007772 -0 0.069986 0 1e-06 0</pose>
        <scale>1 1 1</scale>
        <link name='base_link'>
          <pose>0.007772 -0 0.069986 0 1e-06 0</pose>
          <velocity>-1.3e-05 2e-06 -0.001029 0 0.00056 3e-06</velocity>
          <acceleration>-0 -0 0 0 -0 0</acceleration>
          <wrench>-2e-06 -0 0 0 -0 0</wrench>
        </link>
        <link name='wheel_back_left'>
          <pose>-0.167228 0.2 0.069987 -1.5708 0.050625 0</pose>
          <velocity>-1.3e-05 1e-06 -0.000931 -1.2e-05 0.000483 2e-06</velocity>
          <acceleration>2.6e-05 -0.000493 9.8e-05 -0.012669 -0.07705 -0.001011</acceleration>
          <wrench>1e-05 -0.000185 3.7e-05 0 -0 0</wrench>
        </link>
        <link name='wheel_back_right'>
          <pose>-0.167228 -0.2 0.069987 -1.5708 0.050625 0</pose>
          <velocity>-1.2e-05 1e-06 -0.000932 -1.3e-05 0.000497 2e-06</velocity>
          <acceleration>-5.3e-05 -0.000466 -0.00012 -0.013063 -0.062485 -0.001105</acceleration>
          <wrench>-2e-05 -0.000175 -4.5e-05 0 -0 0</wrench>
        </link>
        <link name='wheel_front_left'>
          <pose>0.182772 0.2 0.069986 -1.5708 0.050625 0</pose>
          <velocity>-1.3e-05 2e-06 -0.001127 -2.5e-05 0.000624 2e-06</velocity>
          <acceleration>2.5e-05 -0.000537 0.000103 -0.025578 0.035912 -0.002044</acceleration>
          <wrench>9e-06 -0.000201 3.9e-05 0 -0 0</wrench>
        </link>
        <link name='wheel_front_right'>
          <pose>0.182772 -0.2 0.069986 -1.5708 0.050625 0</pose>
          <velocity>-1.2e-05 1e-06 -0.001127 -2.1e-05 0.00064 2e-06</velocity>
          <acceleration>2.4e-05 -0.000822 -0.000132 -0.021505 0.080375 -0.000945</acceleration>
          <wrench>9e-06 -0.000308 -4.9e-05 0 -0 0</wrench>
        </link>
      </model>
      <model name='willowgarage'>
        <pose>-8.56342 -28.0143 0 0 -0 0</pose>
        <scale>1 1 1</scale>
        <link name='walls'>
          <pose>-8.56342 -28.0143 0 0 -0 0</pose>
          <velocity>0 0 0 0 -0 0</velocity>
          <acceleration>0 0 0 0 -0 0</acceleration>
          <wrench>0 0 0 0 -0 0</wrench>
        </link>
      </model>
      <light name='sun'>
        <pose>0 0 10 0 -0 0</pose>
      </light>
    </state>
    <gui fullscreen='0'>
      <camera name='user_camera'>
        <pose>2.71973 -1.35317 19.5267 3.14159 1.57079 3.14159</pose>
        <view_controller>orbit</view_controller>
        <projection_type>perspective</projection_type>
      </camera>
    </gui>
    <model name='willowgarage'>
      <static>1</static>
      <pose>4.64768 -24.2079 0 0 -0 0</pose>
      <link name='walls'>
        <collision name='collision'>
          <geometry>
            <mesh>
              <uri>model://willowgarage/meshes/willowgarage_collision.dae</uri>
            </mesh>
          </geometry>
          <max_contacts>10</max_contacts>
          <surface>
            <contact>
              <ode/>
            </contact>
            <bounce/>
            <friction>
              <torsional>
                <ode/>
              </torsional>
              <ode/>
            </friction>
          </surface>
        </collision>
        <visual name='visual'>
          <geometry>
            <mesh>
              <uri>model://willowgarage/meshes/willowgarage_visual.dae</uri>
            </mesh>
          </geometry>
          <cast_shadows>0</cast_shadows>
        </visual>
        <self_collide>0</self_collide>
        <enable_wind>0</enable_wind>
        <kinematic>0</kinematic>
      </link>
    </model>
  </world>
</sdf>
